ERREUR RENCONTRÃ‰E LORS DE LA TENTATIVE 2:

2025-03-31 02:46:41.157 Python[79501:11344280] +[IMKClient subclass]: chose IMKClient_Modern
2025-03-31 02:46:41.157 Python[79501:11344280] +[IMKInputSession subclass]: chose IMKInputSession_Modern
Traceback (most recent call last):
  File "/var/folders/cd/tvhvrzsn1tl2my4ys69gv6wm0000gn/T/analysis_20250331_024457_vyuggmr3/analysis_script.py", line 670, in <module>
    vif_data["VIF"] = [variance_inflation_factor(X.values, i) for i in range(X.shape[1])]
                       ~~~~~~~~~~~~~~~~~~~~~~~~~^^^^^^^^^^^^^
  File "/Users/pierreandrews/Desktop/AgentPro/venv/lib/python3.13/site-packages/statsmodels/stats/outliers_influence.py", line 196, in variance_inflation_factor
    r_squared_i = OLS(x_i, x_noti).fit().rsquared
                  ~~~^^^^^^^^^^^^^
  File "/Users/pierreandrews/Desktop/AgentPro/venv/lib/python3.13/site-packages/statsmodels/regression/linear_model.py", line 921, in __init__
    super().__init__(endog, exog, missing=missing,
    ~~~~~~~~~~~~~~~~^^^^^^^^^^^^^^^^^^^^^^^^^^^^^^
                              hasconst=hasconst, **kwargs)
                              ^^^^^^^^^^^^^^^^^^^^^^^^^^^^
  File "/Users/pierreandrews/Desktop/AgentPro/venv/lib/python3.13/site-packages/statsmodels/regression/linear_model.py", line 746, in __init__
    super().__init__(endog, exog, missing=missing,
    ~~~~~~~~~~~~~~~~^^^^^^^^^^^^^^^^^^^^^^^^^^^^^^
                              weights=weights, hasconst=hasconst, **kwargs)
                              ^^^^^^^^^^^^^^^^^^^^^^^^^^^^^^^^^^^^^^^^^^^^^
  File "/Users/pierreandrews/Desktop/AgentPro/venv/lib/python3.13/site-packages/statsmodels/regression/linear_model.py", line 200, in __init__
    super().__init__(endog, exog, **kwargs)
    ~~~~~~~~~~~~~~~~^^^^^^^^^^^^^^^^^^^^^^^
  File "/Users/pierreandrews/Desktop/AgentPro/venv/lib/python3.13/site-packages/statsmodels/base/model.py", line 270, in __init__
    super().__init__(endog, exog, **kwargs)
    ~~~~~~~~~~~~~~~~^^^^^^^^^^^^^^^^^^^^^^^
  File "/Users/pierreandrews/Desktop/AgentPro/venv/lib/python3.13/site-packages/statsmodels/base/model.py", line 95, in __init__
    self.data = self._handle_data(endog, exog, missing, hasconst,
                ~~~~~~~~~~~~~~~~~^^^^^^^^^^^^^^^^^^^^^^^^^^^^^^^^
                                  **kwargs)
                                  ^^^^^^^^^
  File "/Users/pierreandrews/Desktop/AgentPro/venv/lib/python3.13/site-packages/statsmodels/base/model.py", line 135, in _handle_data
    data = handle_data(endog, exog, missing, hasconst, **kwargs)
  File "/Users/pierreandrews/Desktop/AgentPro/venv/lib/python3.13/site-packages/statsmodels/base/data.py", line 675, in handle_data
    return klass(endog, exog=exog, missing=missing, hasconst=hasconst,
                 **kwargs)
  File "/Users/pierreandrews/Desktop/AgentPro/venv/lib/python3.13/site-packages/statsmodels/base/data.py", line 88, in __init__
    self._handle_constant(hasconst)
    ~~~~~~~~~~~~~~~~~~~~~^^^^^^^^^^
  File "/Users/pierreandrews/Desktop/AgentPro/venv/lib/python3.13/site-packages/statsmodels/base/data.py", line 133, in _handle_constant
    if not np.isfinite(exog_max).all():
           ~~~~~~~~~~~^^^^^^^^^^
TypeError: ufunc 'isfinite' not supported for the input types, and the inputs could not be safely coerced to any supported types according to the casting rule ''safe''
